Reading using 16 cores
Spwaning 4 processes
multiprocessing.pool.RemoteTraceback: 
"""
Traceback (most recent call last):
  File "/home/hrb/.conda/envs/astroconda/lib/python3.6/multiprocessing/pool.py", line 119, in worker
    result = (True, func(*args, **kwds))
  File "/home/hrb/.conda/envs/astroconda/lib/python3.6/multiprocessing/pool.py", line 44, in mapstar
    return list(map(*args))
  File "/home/hrb/qso_photometry/python/module/preprocessing/data_io.py", line 19, in reader
    with open(basepath+'lc_{}.csv'.format(i)) as file:
FileNotFoundError: [Errno 2] No such file or directory: '/home/hrb/qso_photometry/data/surveys/ztf,/qsos,/unclean/g,_band/lc_0.csv'
"""

The above exception was the direct cause of the following exception:

Traceback (most recent call last):
  File "scripts/average_nightly_observations.py", line 39, in <module>
    df = data_io.dispatch_reader(kwargs, multiproc=True)
  File "/home/hrb/qso_photometry/python/module/preprocessing/data_io.py", line 43, in dispatch_reader
    df = pool.map(reader, [(j, kwargs) for j in range(n_files)])
  File "/home/hrb/.conda/envs/astroconda/lib/python3.6/multiprocessing/pool.py", line 266, in map
    return self._map_async(func, iterable, mapstar, chunksize).get()
  File "/home/hrb/.conda/envs/astroconda/lib/python3.6/multiprocessing/pool.py", line 644, in get
    raise self._value
FileNotFoundError: [Errno 2] No such file or directory: '/home/hrb/qso_photometry/data/surveys/ztf,/qsos,/unclean/g,_band/lc_0.csv'
